Workbook

Sheet SLP Training Calls
A1: SLP List Assembly: Govindganj Training Date & Time: 17th June 2025, 10:30 AM Location: Cold Store Balaha chowk, Areraj Field Coordinator: Jamshed Alam | D1: Calling Status | E1: Confirmation Status | F1: Remarks
E4: Yes
A6: Sr. No. | B6: Name | C6: Mobile Number
A7: 1 | B7: Khursheed Alam | C7: 9934209607 | D7: Connected | J7: Assembly | K7: No. of SLP said YES on calll
A8: 2 | B8: Prakash Ram | C8: 9693341843 | D8: Busy | J8: Govindganj | K8: 15 | L8: out of 24
A9: 3 | B9: Jubair Alam | C9: 6209101020 | D9: Connected | E9: Yes | J9: Kusheshwar Asthan | K9: 20 | L9: out of 20
A10: 4 | B10: Shabana Khatoon | C10: 7763978358 | D10: Connected | E10: Yes | J10: Bachhwara | K10: 16 | L10: out of 29
A11: 5 | B11: Saheb Alam | C11: 7976710026 | D11: Not Received
A12: 6 | B12: Sunil Ram | C12: 9507519092 | D12: Connected | E12: Yes
A13: 7 | B13: Munna Giri | C13: 9006395334 | D13: Connected | E13: Yes
A14: 8 | B14: Rajnish Kr Thakur | C14: 7739022508 | D14: Switch off
A15: 9 | B15: Md Neyaz | C15: 9810208394 | D15: Connected | E15: Yes
A16: 10 | B16: Suraj Ram | C16: 9771527610 | D16: Wrong No.
A17: 11 | B17: Pankaj Sah | C17: 7903957057 | D17: Connected | E17: Yes
A18: 12 | B18: MunniLal Ram | C18: 7766832315 | D18: Connected | E18: Yes
A19: 13 | B19: Aftab Alam | C19: 9931510786 | D19: Connected | E19: Yes
A20: 14 | B20: Jamadaar Patel | C20: 7372804950 | D20: Connected | E20: Yes
A21: 15 | B21: Md Eqbal | C21: 7352750886 | D21: Switch off
A22: 16 | B22: Md Moin | C22: 9973560056 | D22: Connected | E22: No | F22: note come
A23: 17 | B23: Jairam Yadav | C23: 9525313845 | D23: Connected | E23: Yes
A24: 18 | B24: Md Samiullah | C24: 9523008283 | D24: Connected | E24: Yes
A25: 19 | B25: Rajesh Kr Gupta | C25: 9973138077 | D25: Connected | E25: Yes
A26: 20 | B26: Mukesh Kumar | C26: 9523624880 | D26: Connected | E26: Yes
A27: 21 | B27: Pintu Thakur | C27: 9199994194 | D27: Connected | E27: Yes
A28: 22 | B28: Rambabu Kumar | C28: 8521461956 | D28: Switch off
A29: 23 | B29: Shobha Devi | C29: 7370941803 | D29: Not Received
A30: 24 | B30: Zahir Hussain | C30: 9955161629 | D30: Connected | E30: Yes
A32: SLP List Assembly: Bachhwara Training Date & Time: 18th June 2025, Location: Field Coordinator: Niraj Kumar
A37: Sr. No. | B37: Name | C37: Mobile Number
A38: 1 | B38: Sintu Kumar | C38: 7546922084 | D38: Connected | E38: Yes
A39: 2 | B39: Arvind Kumar | C39: 7488681191 | D39: Connected | E39: Yes
A40: 3 | B40: Rohit Kumar | C40: 7488613599 | D40: Busy | E40: Yes
A41: 4 | B41: Om Prakash | C41: 9801705676 | D41: Connected | E41: Yes
A42: 5 | B42: Nandlal Chaurasia | C42: 9006236888 | D42: Connected | E42: Yes
A43: 6 | B43: Nitish Kumar | C43: 6200660447 | D43: Call Back Later
A44: 7 | B44: Awadhesh Kumar | C44: 6200838371 | D44: Connected | E44: Yes
A45: 8 | B45: Ajay Kumar | C45: 6207659784 | D45: Connected | E45: Yes
A46: 9 | B46: Ranjit Yadav | C46: 9709629052 | D46: Connected | E46: Yes
A47: 10 | B47: Vikas Kumar | C47: 7903546800 | D47: Busy
A48: 11 | B48: Raju Kumar | C48: 8271784711 | D48: Switch off
...

Sheet SLP Field Data
A1: ASSEMBLY COORDINATOR (LEADER NAME) | B1: NAME | C1: NUMBER | D1: AGE | E1: GENDER | F1: PROFESSION | G1: RELIGION | H1: CATEGORY | I1: CASTE | J1: DISTRICT | K1: ASSEMBLY | L1: BLOCK | M1: PANCHAYAT | N1: Calling Status | O1: 1. क्या आप राजनीतिक या सामाजिक कार्य में रूचि रखते हैं? (हां/नहीं) | P1: 2. क्या आप वर्तमान में किसी सामाजिक या राजनैतिक संगठन से जुड़े हैं? (हाँ / नहीं) | Q1: संगठन का नाम (यदि हाँ): | R1: भूमिका (1-2 शब्द): | S1: 3. आपने अब तक अपने क्षेत्र में कोई सामाजिक या जन सरोकार का कार्य किया है? (हाँ / नहीं) | T1: यदि हाँ, तो एक उदाहरण दें: | U1: 4. क्या आपने कभी किसी जनप्रतिनिधि से जनता के मुद्दों को लेकर बात की है? (हाँ / नहीं) | V1: यदि हाँ, तो मुद्दा: | W1: 5. सामाजिक न्याय और समानता आपके लिए कितनी महत्वपूर्ण है? (बहुत / कुछ हद तक / नहीं) | X1: 6. क्या आप मानते हैं कि भारतीय संविधान की बातें – न्याय, स्वतंत्रता, समानता, बंधुत्व – ज़मीनी स्तर तक पहुंचें? (हाँ / नहीं) | Y1: 7. क्या आप कांग्रेस पार्टी द्वारा चलाए जा रहे संविधान लीडरशिप प्रोग्राम के बारे में जानते हैं? (हां/नहीं) (यदि नहीं तो संविधान लीडरशिप प्रोग्राम के बारे में जानकारी- ) | Z1: 8. क्या आप इस प्रोग्राम में नेतृत्व की भूमिका निभाने को तैयार हैं? (हाँ / नहीं / विचार कर रहा/रही हूं) | AA1: Verification Status | AB1: Remarks
A2: CHANDAN KUMAR | B2: Uma Shankar Roy | C2: 9507689463 | E2: Male | K2: ROSERA | N2: Not Received | AB2: market me hain baad me call karenge khud se
B3: Sunil Kumar | C3: 8434416844 | D3: 23 | E3: Male | F3: student | G3: hindu | K3: ROSERA | N3: Switch off | AB3: didn't agree to provide details
B4: Subodh Kumar | C4: 9525643915 | D4: 25 | E4: Male | F4: farmer | G4: Hindu | H4: OBC | I4: yadav | J4: samastipur | K4: ROSERA | L4: Rosera | N4: Connected | O4: Yes | P4: NO | S4: NO | U4: NO | AB4: call disconnect kar diya gaya
B5: Mukesh Kumar | C5: 8051281222 | D5: 25 | E5: Male | F5: student | G5: hindu | H5: obc | I5: yadav | J5: samastipur | K5: ROSERA | L5: rosera | M5: taher bseriya | N5: Connected | O5: Yes | P5: Yes | Q5: congress | S5: Yes | T5: social activist | U5: Yes | V5: rashan card, oldage pension | W5: Yes | X5: Yes | Y5: Yes | Z5: Yes | AA5: Verified
B6: Bipin Kumar | C6: 7370981710 | K6: ROSERA | N6: Not Received | AD6: bol rhe hai main sab details bata diya hai but meri baat nahi hui h inse
B7: Rishu Raman | C7: 8298316114 | D7: 25 | E7: Male | F7: student | G7: hindu | H7: obc | I7: yadav | J7: samastipur | K7: ROSERA | L7: shivajinagar | M7: kariyan | N7: Connected | O7: Yes | P7: NO | S7: NO | U7: NO | W7: Yes | X7: Yes | Y7: Yes | Z7: Yes | AA7: Verified | AD7: eligible
B8: Sunil Kumar | C8: 9525930962 | K8: ROSERA | N8: Call Back Later | AC8: bol rhe h Avi time nhi h | AD8: connect nahi ho paya off hai ya network se bahar hai
B9: Chandan Kumar | C9: 8877335426 | D9: 28 | E9: Male | F9: student | G9: hindu | H9: obc | I9: yadav | J9: samastipur | K9: ROSERA | L9: rosera | M9: tehar beseriya | N9: Connected | O9: Yes | P9: NO | S9: NO | U9: NO | W9: Yes | X9: Yes | Y9: Yes | Z9: Yes | AA9: Verified | AB9: kaam karwaya ja sakta hai.
B10: Rajan Kumar | C10: 9931256983 | K10: ROSERA | N10: Switch off | AB10: not incoming
B11: Bhukhli Devi | C11: 7367934354 | D11: 40 | E11: Female | F11: labour | G11: hindu | H11: sc | I11: paswan | J11: samastipur | K11: ROSERA | L11: rosera | M11: tehar beseriya | N11: Connected | O11: NO | P11: NO | S11: NO | U11: NO | W11: Yes | X11: Yes | Y11: NO | Z11: NO | AA11: Not Verified | AB11: nahi ho paega inse
B12: Vinod Yadav | C12: 9006220735 | D12: 43 | E12: Male | K12: ROSERA | N12: Connected | AC12: out of Bihar (Dehli) | AD12: baad me baat karenge job pe hain
B13: Kirtan Rajak | C13: 9741143274 | K13: ROSERA | N13: Connected | AB13: recv nhi kr rhe
B14: Raj Kumar Das | C14: 7011766399 | D14: 25 | E14: Male | F14: student | G14: hindu | H14: ebc | I14: das | J14: samastipur | K14: ROSERA | L14: rosera | M14: tehar beseriya | N14: Connected | O14: NO | P14: NO | S14: NO | U14: NO | W14: Yes | X14: Yes | Y14: NO | Z14: Yes | AA14: Verified
B15: Sarita Devi | C15: — | K15: ROSERA | N15: Wrong No. | AB15: contact not available
B16: Sunil Kumar | C16: 7988976975 | K16: ROSERA | N16: Not Received | AB16: recv nhi kar rhe hn | AC16: Busy aa rha h
B17: Manoj Kumar | C17: 9525642852 | K17: ROSERA | N17: Connected | AB17: recv nhi kar rhe hn
B18: Rajesh Roy | C18: 7431922495 | K18: ROSERA | N18: Wrong No. | AB18: wrong number
B19: Pankaj Das | C19: 6287334301 | D19: 27 | E19: Male | F19: job | G19: hindu | H19: obv | I19: das | J19: samastipur | K19: ROSERA | L19: hasanpur | M19: tehar beseriya | N19: Connected | O19: Yes | P19: Yes | Q19: bjp | S19: NO | U19: NO | W19: NO | X19: Yes | Y19: NO | Z19: NO | AA19: Not Verified | AB19: bjp supporter
B20: Raju Rajak | C20: 9113570636 | E20: Male | K20: ROSERA | N20: Switch off | AB20: koi idea nhi h liberary me hai baad me call karenge aapko
B21: Raj Kumar yadav | C21: 8217360257 | D21: 22 | E21: Male | F21: private work | G21: Hindu | H21: OBC | I21: yadav | J21: samastipur | K21: ROSERA | L21: Rosera | N21: Connected | O21: Yes | P21: NO | S21: NO | U21: NO | W21: Yes | X21: Yes | Y21: Yes | Z21: Yes | AA21: Verified | AB21: recv nahi kar rhe hn truecaller me karnataka ka no hai | AC21: ye Bihar se baher rahte h
B22: Ram Shankar yadav | C22: 9328409612 | D22: 25 | E22: Male | F22: business | G22: Hindu | H22: OBC | I22: yadav | J22: samastipur | K22: ROSERA | L22: Sivaji nager | M22: kariyan | N22: Connected | O22: Yes | P22: Yes | Q22: congress | S22: NO | U22: NO | W22: Yes | X22: Yes | Y22: Yes | Z22: Yes | AA22: Verified | AB22: no band hai.. | AC22: inse baat ho gyi h
B23: Tuntun Prasad | C23: 8809723577 | K23: ROSERA | N23: Call Back Later | AB23: aadmi kahi bahar hai | AC23: bol rhi h avi nhi h
B24: Shil Kumar Roy | C24: 9931688723 | D24: 21 | E24: Male | F24: student | G24: hindu | H24: obc | I24: roy | J24: samastipur | K24: ROSERA | L24: rosera | M24: tehar beseriya | N24: Connected | O24: NO | P24: NO | S24: NO | U24: NO | W24: Yes | X24: Yes | Y24: NO | Z24: NO | AA24: Not Verified | AB24: student preparing for IS
B25: Vikash Kumar | C25: 7549354468 | D25: 27 | E25: Male | F25: private business | G25: hindu | H25: obv | I25: yadav | J25: samastipur | K25: ROSERA | L25: rosera | M25: tehar beseriya | N25: Connected | O25: Yes | P25: NO | S25: NO | U25: NO | W25: Yes | X25: Yes | Y25: NO | Z25: Yes | AA25: Verified | AB25: mauka diya ja sakta hai
B26: Anguri Praveen | C26: 9279115161 | D26: 35 | E26: Female | F26: housewife | G26: muslim | J26: samastipur | K26: ROSERA | L26: rosera | M26: tehar beseriya | N26: Connected | O26: NO | P26: NO | S26: NO | U26: NO | W26: Yes | X26: Yes | Y26: NO | Z26: Yes | AA26: Not Verified | AB26: confused prani hain
B27: Supanjan Kumar | C27: 8581921550 | D27: 24 | E27: Male | F27: student | G27: Hindu | H27: OBC | I27: yadav | J27: samastipur | K27: ROSERA | L27: rosera | M27: tehar beariya | N27: Call Back Later | O27: Yes | P27: Yes | Q27: congress | S27: Yes | U27: Yes | V27: unemployment | W27: Yes | X27: Yes | Y27: Yes | Z27: Yes | AA27: Verified | AB27: ghar pe nahin hain | AC27: inse baat ho.gyi h
B28: Ravish Kumar | C28: 9294998500 | K28: ROSERA | N28: Not Received | AB28: call receive nhi kiya gya | AC28: not received
B29: Nitish Kumar | C29: 9135100301 | K29: ROSERA | N29: Switch off | AB29: no off hai
B30: Praveen | C30: 9570553836 | D30: 19 | E30: Male | F30: student | G30: hindu | H30: obc | I30: yadav | J30: samastipur | K30: ROSERA | L30: shivajinagar | M30: kariyan | N30: Connected | O30: NO | P30: NO | S30: NO | U30: NO | W30: NO | X30: Yes | Y30: NO | Z30: NO | AA30: Not Verified
B31: Chandrasekhar | C31: 7654176258 | D31: 32 | F31: teacher | G31: hindu | H31: obc | I31: yadav | J31: samastipur | K31: ROSERA | L31: shivajinagar | M31: kariyan | N31: Connected | O31: Yes | P31: NO | S31: NO | U31: NO | W31: Yes | X31: Yes | Y31: NO | Z31: NO | AA31: Verified | AB31: mauka milega to accha kaam kar sakte hai
B32: Ikalq | C32: 9576419133 | D32: 21 | K32: ROSERA | N32: Connected | AA32: Not Verified | AB32: not interested at all
B33: Meraj Khan | C33: 8919244660 | K33: ROSERA | N33: Wrong No.
B34: Seraj Khan | C34: 7808552461 | K34: ROSERA | N34: Wrong No.
B35: Rohit Kumar | C35: 7491049631 | K35: ROSERA | N35: Switch off | AB35: not reachable or switch off
B36: Shankar Sahni | C36: — | K36: ROSERA | N36: Wrong No.
B37: Ranjit Sahni | C37: 7809496240 | K37: ROSERA | N37: Wrong No.
B38: Asha Devi | C38: — | K38: ROSERA | N38: Wrong No.
B39: Ram Dulari Devi | C39: — | K39: ROSERA | N39: Wrong No.
B40: Md Wasim | C40: 7491938414 | K40: ROSERA | N40: Wrong No.
...

Sheet LAKHISARAI AC
A1: SLP List Assembly: LAKHISARIA Training Date & Time: 13th Sept, 12pm - 2pm Location: KSS College,Chitranjan Ashram, Congress Office, Lakhisarai Field Coordinator: ASHUTOSH
A8: Sr. No. | B8: Name | C8: Mobile Number | D8: Calling Status 11th Sept | E8: Confirmation Status | F8: Remarks | G8: Calling Status 13th Sept | H8: Confirmation Status | I8: Remarks
A9: 1 | B9: Mamta Kumari | C9: 9507715363 | D9: Connected | E9: CONFIRMED | G9: Connected | H9: NOT CONFIRMED | I9: Bahar aaye h
A10: 2 | B10: Sunil Ram | C10: 7320939575 | D10: Connected | E10: NOT CONFIRMED | F10: out of Bihar gye h | G10: Connected | H10: NOT CONFIRMED | I10: Delhi me h
A11: 3 | B11: Dinesh Chandravanshi | C11: 9031845336 | D11: Connected | E11: CONFIRMED | G11: Connected | H11: CONFIRMED | I11: pahuch rhe h
A12: 4 | B12: Rajeev Kahar | C12: 9097447464 | D12: Connected | E12: CONFIRMED | G12: Connected | H12: CONFIRMED | I12: jaa rhe h
A13: 5 | B13: Sanjay Rajak
A14: 6 | B14: Jay prakash Gupta | C14: 9525777797 | D14: Connected | E14: CONFIRMED | G14: Connected | H14: CONFIRMED | I14: jaa rhe h
A15: 7 | B15: Sunil Gupta | C15: 7870221640 | D15: Connected | E15: CONFIRMED | G15: Connected | H15: CONFIRMED | I15: Raste mein h
A16: 8 | B16: Babita Devi | C16: 9065787538 | D16: Connected | E16: CONFIRMED | G16: Not Received
A17: 9 | B17: Akhilesh Yadav | C17: 9572397596 | D17: Connected | E17: CONFIRMED | G17: Not Received
A18: 10 | B18: Uma Bharti | C18: 9006355200 | D18: Connected | E18: CONFIRMED | G18: Not Received
A19: 11 | B19: Radha Kumari | C19: 9934038031 | D19: Connected | E19: CONFIRMED | G19: Switch off
A20: 12 | B20: Rachit Ram | C20: 8084364396 | D20: Connected | E20: CONFIRMED | G20: Connected | H20: NOT CONFIRMED | I20: Nhi jayenge
A21: 13 | B21: Vasant Manjhi | C21: 8521959005 | D21: Connected | E21: CONFIRMED | G21: Not Received
A22: 14 | B22: Manoj Ram | C22: 9576811510, 6203911406 | D22: Connected | E22: CONFIRMED | G22: Connected | H22: CONFIRMED
A23: 15 | B23: Bambam Paswan | C23: 7004044848, 7633919829 | D23: Wrong No. | G23: Connected | I23: wrong no
A24: 16 | B24: Ram kumar Paswan | C24: 6203281834 | D24: Connected | E24: CONFIRMED | G24: Not Received
A25: 17 | B25: Rekha Devi | C25: 8292547763 | D25: Connected | E25: CONFIRMED | G25: Connected | H25: CONFIRMED | I25: Pahuch gye h
A26: 18 | B26: Vishakha Kumari | C26: 9031366194 | D26: Connected | E26: CONFIRMED | G26: Not Received
A27: 19 | B27: Ganga Rajak | C27: 7970406319 | D27: Connected | E27: CONFIRMED | G27: Connected | H27: CONFIRMED | I27: Pahuch gye h
A28: 20 | B28: Harish Kumar Pandey | C28: 9097369597 | D28: Connected | E28: CONFIRMED | G28: Connected | H28: CONFIRMED
A29: 21 | B29: Prem Kumar Sinha
A30: 22 | B30: Naval Ram | C30: 7549954288 | D30: Connected | E30: CONFIRMED | G30: Connected | H30: NOT CONFIRMED | I30: Bahar Hai abhi
A31: 23 | B31: Md. Waris | C31: 9504044988 | D31: Connected | E31: CONFIRMED | G31: Connected | H31: NOT CONFIRMED | I31: kuch kaam tha nhi aayenge
A32: 24 | B32: Vikas Sahu | C32: 7488799643 | D32: Connected | E32: CONFIRMED | G32: Connected | H32: CONFIRMED
A33: 25 | B33: Pintu Thakur | C33: 6204476435 | D33: Connected | E33: CONFIRMED | G33: Not Received
A34: 26 | B34: Arvind Yadav | C34: 8804953630 | D34: Connected | E34: CONFIRMED | G34: Connected | H34: CONFIRMED
A35: 27 | B35: Anandi Bind | C35: 8603064834 | D35: Connected | E35: CONFIRMED | G35: Connected | H35: CONFIRMED
A36: 28 | B36: Dayanand Yadav | C36: 8969915789 | D36: Connected | E36: CONFIRMED | G36: Connected | H36: CONFIRMED
A37: 29 | B37: Raana Yadav | C37: 8210611872 | D37: Connected | E37: CONFIRMED | G37: Switch off
A38: 30 | B38: ShivNandan Mahto | C38: 9852567270 | D38: Not Received | G38: Not Received
A39: 31 | B39: Annapurna Devi | C39: 7061618704 | D39: Connected | E39: CONFIRMED | G39: Not Received
A40: 32 | B40: Pankaj Kumar Verma | C40: 9472226808 | D40: Connected | E40: CONFIRMED | G40: Connected | H40: NOT CONFIRMED | I40: Nhi jayenge
A41: 33 | B41: Sarita Devi | C41: 8340599978 | D41: Connected | E41: CONFIRMED | G41: Connected | H41: CONFIRMED
A42: 34 | B42: Choti Khatton | C42: 6205369824 | D42: Connected | E42: CONFIRMED | G42: Connected | H42: NOT CONFIRMED
A43: 35 | B43: Roshan Khatoon | C43: 8252208657 | D43: Connected | E43: CONFIRMED | G43: Busy
A44: 36 | B44: Kameshwar Manjhi | C44: 8210916152 | D44: Connected | E44: CONFIRMED | G44: Busy
A45: 37 | B45: Ajay Yadav | C45: 6207116440 | D45: Connected | E45: CONFIRMED | G45: Not Received
A46: 38 | B46: Neeraj mandal | C46: 8581894200 | D46: Connected | E46: CONFIRMED | G46: Not Received
...

Sheet HARLAKHI AC
A1: SLP List Assembly: HARLAKHI Training Date & Time: 4TH SEPTEMBER Location:-UMGAON Field Coordinator: ZARTAB ALAM
A6: Sr. No. | B6: Name | C6: Mobile Number | E6: Calling Status 3rd September | F6: Confirmation Status
B7: Hariom Kumar | C7: 7050720310 | E7: Call Back Later
A8: 2 | B8: Bhavem Kumar Mahto | C8: 7050499388 | E8: Wrong No.
A9: 3 | B9: Jyoti Kumari | C9: 6200854663 | E9: Call Back Later
A10: 4 | B10: Ramam Spasht | C10: 8298179247 | E10: Connected
A11: 5 | B11: Anjali Kumari | C11: 8340248951 | E11: Connected | F11: CONFIRMED
A12: 6 | B12: Gokulanand Jhap | C12: 7260869523 | E12: Switch off
A13: 7 | B13: Subhash Yadav | C13: 7488340121 | E13: Switch off
A14: 8 | B14: Vivek Kumar Mahto | C14: 9661084733 | E14: Connected | F14: CONFIRMED
A15: 9 | B15: Anjali Kumari | C15: 6201897459 | E15: Switch off
A16: 10 | B16: Sitesh Kumar Paswan | C16: 9631275390 | E16: Connected | F16: NOT CONFIRMED
A17: 11 | B17: Govind Mahto | C17: 9973734918 | E17: Connected | F17: CONFIRMED
A18: 12 | B18: Naresh Shah | C18: 8084651416 | E18: Connected
A19: 13 | B19: Md Sohail | C19: 7764079174 | E19: Connected
A20: 14 | B20: Mohammad Shafique | C20: 9871828656 | E20: Connected | F20: CONFIRMED
A21: 15 | B21: Naresh | C21: 7070832712 | E21: Connected
A24: ASSEMBLY COORDINATOR (LEADER NAME) | B24: NAME | C24: NUMBER | E24: AGE | F24: GENDER | G24: PROFESSION | H24: RELIGION | I24: CATEGORY | J24: CASTE | K24: DISTRICT | L24: ASSEMBLY | M24: BLOCK | N24: PANCHAYAT | O24: Calling Status | P24: 1. क्या आप राजनीतिक या सामाजिक कार्य में रूचि रखते हैं? (हां/नहीं) | Q24: 2. क्या आप वर्तमान में किसी सामाजिक या राजनैतिक संगठन से जुड़े हैं? (हाँ / नहीं) | R24: संगठन का नाम (यदि हाँ): | S24: भूमिका (1-2 शब्द): | T24: 3. आपने अब तक अपने क्षेत्र में कोई सामाजिक या जन सरोकार का कार्य किया है? (हाँ / नहीं) | U24: यदि हाँ, तो एक उदाहरण दें: | V24: 4. क्या आपने कभी किसी जनप्रतिनिधि से जनता के मुद्दों को लेकर बात की है? (हाँ / नहीं) | W24: यदि हाँ, तो मुद्दा: | X24: 5. सामाजिक न्याय और समानता आपके लिए कितनी महत्वपूर्ण है? (बहुत / कुछ हद तक / नहीं) | Y24: 6. क्या आप मानते हैं कि भारतीय संविधान की बातें – न्याय, स्वतंत्रता, समानता, बंधुत्व – ज़मीनी स्तर तक पहुंचें? (हाँ / नहीं) | Z24: 7. क्या आप कांग्रेस पार्टी द्वारा चलाए जा रहे संविधान लीडरशिप प्रोग्राम के बारे में जानते हैं? (हां/नहीं) (यदि नहीं तो संविधान लीडरशिप प्रोग्राम के बारे में जानकारी- ) | AA24: 8. क्या आप इस प्रोग्राम में नेतृत्व की भूमिका निभाने को तैयार हैं? (हाँ / नहीं / विचार कर रहा/रही हूं) | AB24: Verification Status | AC24: Remarks
B25: Hariom Kumar | C25: 7050720310 | E25: 22 | F25: Male | K25: Madhubani | L25: Harlakhi | O25: Call Back Later
B26: Bhavem Kumar Mahto | C26: 7050499388 | K26: Madhubani | L26: Harlakhi | O26: Wrong No.
B27: Jyoti Kumari | C27: 6200854663 | E27: 24 | F27: Female | G27: no | H27: Hindu | I27: obc | K27: Madhubani | L27: Harlakhi | M27: harlakhi | O27: Call Back Later
B28: Ramam Spasht | C28: 8298179247 | E28: 25 | F28: Male | G28: ward | H28: Hindu | J28: teli | K28: Madhubani | L28: Harlakhi | O28: Connected | AC28: sahi se baat nahin kar raha hai बार-बार call Kat de raha hai
B29: Anjali Kumari | C29: 8340248951 | E29: 19 | F29: Female | G29: no | H29: Hindu | I29: ebc | K29: Madhubani | L29: Harlakhi | M29: harlakhi | N29: harlakhi | O29: Connected | P29: Yes | Q29: NO | Z29: NO | AA29: Yes | AB29: Verified
B30: Gokulanand Jhap | C30: 7260869523 | K30: Madhubani | L30: Harlakhi | O30: Switch off
B31: Subhash Yadav | C31: 7488340121 | K31: Madhubani | L31: Harlakhi | O31: Switch off
B32: Vivek Kumar Mahto | C32: 9661084733 | D32: 19 | E32: 19 | F32: Male | G32: no | H32: Hindu | I32: obc | J32: kuswaha | K32: Madhubani | L32: Harlakhi | M32: harlakhi | N32: harlakhi | O32: Connected | P32: Yes | Q32: NO | Z32: NO | AA32: Yes | AB32: Verified
B33: Anjali Kumari | C33: 6201897459 | K33: Madhubani | L33: Harlakhi | O33: Switch off
B34: Sitesh Kumar Paswan | C34: 9631275390 | E34: 29 | F34: Male | G34: no | H34: Hindu | I34: sc | J34: paswan | K34: Madhubani | L34: Harlakhi | M34: benipatti | N34: akur | O34: Connected | P34: Yes | Q34: Yes | R34: congress | Z34: Yes | AA34: Yes | AB34: Not Verified | AC34: state secretary( IYC)
B35: Govind Mahto | C35: 9973734918 | E35: 33 | F35: Male | G35: ward | H35: Hindu | I35: ebc | J35: mahato | K35: Madhubani | L35: Harlakhi | M35: harlakhi | N35: gor harhar | O35: Connected | P35: Yes | Q35: Yes | R35: rjd | S35: warker | Z35: Yes | AA35: Yes | AB35: Verified
B36: Naresh Shah | C36: 8084651416 | E36: 43 | F36: Male | H36: Hindu | I36: obc | K36: Madhubani | L36: Harlakhi | M36: harlakhi | O36: Connected | AC36: bhole ki jartabalam se baat karenge tab aapse baat karenge aur call Kat Diya
B37: Md Sohail | C37: 7764079174 | K37: Madhubani | L37: Harlakhi | O37: Connected | AC37: iska Madhubani vidhansabha hai
B38: Mohammad Shafique | C38: 9871828656 | E38: 41 | F38: Male | G38: no | H38: muslim | I38: sc | J38: rain | K38: Madhubani | L38: Harlakhi | M38: suthgao | N38: umgaon | O38: Connected | P38: Yes | Q38: NO | Z38: Yes | AA38: Yes | AB38: Verified
B39: Naresh | C39: 7070832712 | K39: Madhubani | L39: Harlakhi | O39: Connected | AC39: poochhne ke bad call Kat Diya

Sheet WAZIRGANJ AC
A1: SLP List Assembly: WAZIRGANJ Training Date & Time: 7th AUGUST, 1:00 PM Location:RAGHUNANDAN JI RESTURANT , GAYA NAWAD ROAD(NEAR FLYDINE RESTURANT) Field Coordinator:PRANAV
A8: Sr. No. | B8: Name | C8: Mobile Number | D8: 26th July Calling Status | E8: Confirmation Status | F8: Remarks
A9: 1 | B9: Ishwar Dayal | C9: 8757711231 | D9: Not Received
A10: 2 | B10: Ranjeet Kumar | C10: 7857823003 | D10: Connected
A11: 3 | B11: Vikram Kumar | C11: 9955738758 | D11: Not Received
A12: 4 | B12: Deepak Kumar | C12: 766764867 | D12: Wrong No.
A13: 5 | B13: Shiv Shankar | C13: 6202559388 | D13: Not Received
A14: 6 | B14: Praveen Kumar | C14: 9690245343 | D14: Connected
A15: 7 | B15: Mohit Kumar | C15: 9693505248
A16: 8 | B16: Sanjay Kumar | C16: 9471839543
A17: 9 | B17: Dhirendar Kumar | C17: 9097018111 | D17: Connected
A18: 10 | B18: Chhotu Kumar | C18: 8229059662 | D18: Connected
A19: 11 | B19: Raushan Kumar | C19: 8757014710 | D19: Connected
A20: 12 | B20: Dindayal Kumar | C20: 9304531815 | D20: Call Back Later
A21: 13 | B21: Ajay Kumar | C21: 8709839243 | D21: Connected
A22: 14 | B22: Sujit Kumar | C22: 9142773498 | D22: Not Received
A23: 15 | B23: Vinay Kumar | C23: 9708837524 | D23: Connected
A24: 16 | B24: Ravi Kumar | C24: 7903413989 | D24: Connected
A25: 17 | B25: Nagendra Kumar | C25: 9155758492 | D25: Connected
A26: 18 | B26: Vikash Kumar | C26: 7739730459 | D26: Connected
A27: 19 | B27: Akash Kumar | C27: 7903009934 | D27: Connected
A28: 20 | B28: Rajeev Kumar | C28: 9262260506 | D28: Connected
... A34: 26 | B34: Nitish Kumar | C34: 6209661405 | D34: Connected
A37: ASSEMBLY COORDINATOR (LEADER NAME) | B37: NAME | C37: NUMBER | D37: AGE | E37: GENDER | F37: PROFESSION | G37: RELIGION | H37: CATEGORY | I37: CASTE | J37: DISTRICT | K37: ASSEMBLY | L37: BLOCK | M37: PANCHAYAT | N37: Calling Status | O37: 1. क्या आप राजनीतिक या सामाजिक कार्य में रूचि रखते हैं? (हां/नहीं) | P37: 2. क्या आप वर्तमान में किसी सामाजिक या राजनैतिक संगठन से जुड़े हैं? (हाँ / नहीं) | Q37: संगठन का नाम (यदि हाँ): | R37: भूमिका (1-2 शब्द): | S37: 3. आपने अब तक अपने क्षेत्र में कोई सामाजिक या जन सरोकार का कार्य किया है? (हाँ / नहीं) | T37: यदि हाँ, तो एक उदाहरण दें: | U37: 4. क्या आपने कभी किसी जनप्रतिनिधि से जनता के मुद्दों को लेकर बात की है? (हाँ / नहीं) | V37: यदि हाँ, तो मुद्दा: | W37: 5. सामाजिक न्याय और समानता आपके लिए कितनी महत्वपूर्ण है? (बहुत / कुछ हद तक / नहीं) | X37: 6. क्या आप मानते हैं कि भारतीय संविधान की बातें – न्याय, स्वतंत्रता, समानता, बंधुत्व – ज़मीनी स्तर तक पहुंचें? (हाँ / नहीं) | Y37: 7. क्या आप कांग्रेस पार्टी द्वारा चलाए जा रहे संविधान लीडरशिप प्रोग्राम के बारे में जानते हैं? (हां/नहीं) (यदि नहीं तो संविधान लीडरशिप प्रोग्राम के बारे में जानकारी- ) | Z37: 8. क्या आप इस प्रोग्राम में नेतृत्व की भूमिका निभाने को तैयार हैं? (हाँ / नहीं / विचार कर रहा/रही हूं) | AA37: Verification Status | AB37: Remarks
A38: PRANAV | B38: Ishwar Dayal | C38: 8757711231 | J38: GAYA | K38: WAZIRGANJ | N38: Not Received
B39: Ranjeet Kumar | C39: 7857823003 | J39: GAYA | K39: WAZIRGANJ | N39: Connected | AB39: not interested
B40: Vikram Kumar | C40: 9955738758 | J40: GAYA | K40: WAZIRGANJ | N40: Not Received
B41: Deepak Kumar | C41: 766764867 | J41: GAYA | K41: WAZIRGANJ | N41: Wrong No.
B42: Shiv Shankar | C42: 6202559388 | J42: GAYA | K42: WAZIRGANJ | N42: Not Received
B43: Praveen Kumar | C43: 9690245343 | D43: 22 | E43: Male | F43: business | G43: Hindu | H43: obc | I43: kushvaha | J43: GAYA | K43: WAZIRGANJ | L43: manpur | M43: lakhanpur | N43: Connected | O43: Yes | P43: Yes | Q43: bjp | R43: waker
B44: Mohit Kumar | C44: 9693505248 | J44: GAYA | K44: WAZIRGANJ | N44: NOT INTRESTED
B45: Sanjay Kumar | C45: 9471839543 | J45: GAYA | K45: WAZIRGANJ | N45: NOT INTRESTED | AB45: hamare pass samay nahin Hai meeting mein nahin Ja payenge aur call Kat Diya
B46: Dhirendar Kumar | C46: 9097018111 | D46: 35 | E46: Male | F46: teacher | G46: Hindu | H46: obc | I46: Yadav | J46: GAYA | K46: WAZIRGANJ | L46: manpur | M46: baragedha | N46: Connected | O46: Yes | P46: NO | S46: Yes | U46: Yes | W46: Bahut | X46: Yes | Y46: Yes | Z46: Yes | AA46: Verified
B47: Chhotu Kumar | C47: 8229059662 | D47: 25 | E47: Male | F47: business | G47: Hindu | H47: ebc | I47: lohar | J47: GAYA | K47: WAZIRGANJ | L47: manpur | M47: khusri | N47: Connected | O47: Yes | P47: NO | X47: Yes | Y47: Yes | Z47: Yes | AA47: Verified
B48: Raushan Kumar | C48: 8757014710 | D48: 28 | E48: Male | F48: study | G48: Hindu | H48: ebc | J48: GAYA | K48: WAZIRGANJ | L48: manpur | M48: khusri | N48: Connected | O48: Yes | P48: NO | S48: Yes | U48: Yes | W48: Bahut | X48: Yes | Y48: Yes | Z48: Yes | AA48: Verified
B49: Dindayal Kumar | C49: 9304531815 | J49: GAYA | K49: WAZIRGANJ | N49: Call Back Later | AB49: Sham mein baat hogi
B50: Ajay Kumar | C50: 8709839243 | D50: 35 | E50: Male | F50: bejo gar | G50: Hindu | H50: obc | J50: GAYA | K50: WAZIRGANJ | L50: manpur | M50: ward/47 | N50: Connected | O50: Yes | P50: NO | S50: Yes | U50: Yes | W50: Bahut | X50: Yes | Y50: Yes | Z50: Yes | AA50: Verified
B51: Sujit Kumar | C51: 9142773498 | J51: GAYA | K51: WAZIRGANJ | N51: Not Received
B52: Vinay Kumar | C52: 9708837524 | D52: 32 | E52: Male | F52: business | G52: Hindu | H52: obc | J52: GAYA | K52: WAZIRGANJ | L52: manpur | M52: shadipur | N52: Connected | O52: Yes | P52: Yes | Q52: rdj | R52: Panchayat adhyaksh | S52: Yes | U52: Yes | W52: Bahut | X52: Yes | Y52: Yes | Z52: Yes | AA52: Verified
B53: Ravi Kumar | C53: 7903413989 | J53: GAYA | K53: WAZIRGANJ | N53: Connected | AA53: Verified | AB53: bole ki abhi mere pass samay nahin Hai cal main a jaunga call Kat Diya bike chala raha tha
...

Sheet HARNAUT AC
A1: SLP List Assembly: HARNAUT Training Date & Time: 3rd Sept, 12pm Onwards Location: आशीर्वाद मैरेज हॉल, डाकबंगला रोड, हाई स्कूल हरनौत के पास Field Coordinator: Vivek Kumar
A8: Sr. No. | B8: Name | C8: Mobile Number | D8: Calling Status 1st Sept | E8: Confirmation Status | F8: Remarks | G8: Calling Status 3rd Sept | H8: Confirmation Status | I8: Remarks
A9: 1 | B9: Abhay Kumar | C9: 9931059565 | D9: Connected | E9: CONFIRMED | G9: Connected | H9: CONFIRMED
A10: 2 | B10: Dinesh Jamadar | C10: 7633948045 | D10: Connected | E10: CONFIRMED | G10: Connected | H10: NOT CONFIRMED | I10: nhi aa payenge
A11: 3 | B11: Bacchan Kumar | C11: 7765846551 | D11: Connected | E11: CONFIRMED | G11: Connected | H11: NOT CONFIRMED | I11: tabiyat kharab hai
A12: 4 | B12: Suhani Sinha | C12: 9905487919 | D12: Connected | E12: CONFIRMED | G12: Connected | H12: CONFIRMED
A13: 5 | B13: Sunita Devi | C13: 8002370889 | D13: Connected | E13: CONFIRMED | G13: Not Received
A14: 6 | B14: Jai Prakash Kumar | C14: 9570464752 | D14: Connected | E14: CONFIRMED | G14: Connected | H14: CONFIRMED
A15: 7 | B15: Anjani Kumar | C15: 8969864115 | D15: Call Back Later | G15: Connected | H15: NOT CONFIRMED | I15: Call cut
A16: 8 | B16: Ajit Kumar Ram | C16: 9934272087 | D16: Connected | E16: CONFIRMED | G16: Connected | H16: CONFIRMED
A17: 9 | B17: Urmila Devi | C17: 8735979323 | D17: Connected | E17: CONFIRMED | G17: Connected | H17: CONFIRMED
A18: 10 | B18: Sanoj Kumar | C18: 9525146391 | D18: Connected | E18: CONFIRMED | G18: Not Received
A19: 11 | B19: Sarita Devi | C19: 7549289551 | D19: Connected | E19: CONFIRMED | G19: Connected | H19: NOT CONFIRMED | I19: nhi aa paygi
A20: 12 | B20: Ramuchit Jamadar | C20: 6209662976 | D20: Connected | E20: CONFIRMED | G20: Not Received
A21: 13 | B21: Satyendra Prasad | C21: 9006891188 | D21: Connected | E21: CONFIRMED | G21: Connected | H21: CONFIRMED
A22: 14 | B22: Seema Devi | C22: 6299648310 | D22: Connected | E22: CONFIRMED | G22: Busy | I22: call cut
A23: 15 | B23: Snehlata Kumari | C23: 7004834266 | D23: Connected | E23: CONFIRMED | G23: Switch off
A24: 16 | B24: Usha Devi | C24: 6207400315 | D24: Connected | E24: CONFIRMED | G24: Connected | H24: NOT CONFIRMED | I24: tabiyat thik nahi hai
A25: 17 | B25: Ganga Vishun Jamadar | C25: 7808261928 | D25: Connected | E25: CONFIRMED | G25: Switch off
A26: 18 | B26: Raushan Kumar | C26: 9771401335 | D26: Connected | E26: CONFIRMED | G26: Busy
A27: 19 | B27: Kiran Devi | C27: 9835325070 | D27: Connected | E27: CONFIRMED | G27: Connected | H27: CONFIRMED
A28: 20 | B28: Jayant Kumar Singh | C28: 9693167773 | D28: Connected | E28: CONFIRMED | G28: Connected | H28: NOT CONFIRMED | I28: tabiyat thik nhi h
A29: 21 | B29: Sunita Devi | C29: 9128284927 | D29: Connected | E29: CONFIRMED | G29: Switch off
A30: 22 | B30: Aarti Kumari | C30: 6201871460 | D30: Connected | E30: CONFIRMED | G30: Not Received
A31: 23 | B31: Manti Devi | C31: 8809420961 | D31: Connected | E31: CONFIRMED | G31: Connected | H31: NOT CONFIRMED | I31: tabiyat thik nahi hai
A32: 24 | B32: Shiv Mistri | C32: 8298619559 | D32: Connected | E32: CONFIRMED | G32: Connected | H32: CONFIRMED
A33: 25 | B33: Deenanath Kumar | C33: 8789226099 | D33: Connected | E33: CONFIRMED | G33: Not Received
A34: 26 | B34: Ajay Kumar | C34: 8804532173 | D34: Connected | E34: CONFIRMED | F34: Dekhte h | G34: Connected | H34: NOT CONFIRMED | I34: panchyat me kaam h
A35: 27 | B35: Soni Devi | C35: 8002438548 | D35: Connected | E35: CONFIRMED | G35: Not Received
A36: 28 | B36: Shri Ram Paswan | C36: 8757473940 | D36: Connected | E36: CONFIRMED | G36: Busy
A37: 29 | B37: Mamta Devi | C37: 8292213428 | D37: Connected | E37: NOT CONFIRMED | F37: kolkata gyi h | G37: Connected | H37: NOT CONFIRMED
A38: 30 | B38: Amrita Devi | C38: 8294235217 | D38: Connected | E38: CONFIRMED | G38: Connected | H38: CONFIRMED
A39: 31 | B39: Vipin Kumar | C39: 9162243414 | D39: Connected | E39: CONFIRMED | G39: Not Received
A40: 32 | B40: Kumari Nibha Sinha | C40: 6203312040 | D40: Connected | E40: CONFIRMED | G40: Connected | H40: NOT CONFIRMED
A41: 33 | B41: Reena Devi | C41: 7352752311 | D41: Switch off | G41: Not Received
A42: 34 | B42: Kiran Devi | C42: 9631226508 | D42: Connected | E42: CONFIRMED | G42: Connected | H42: NOT CONFIRMED | I42: fasting ki h
A43: 35 | B43: Sudhir Vind | C43: 9523487308 | D43: Connected | E43: CONFIRMED | G43: Switch off
A44: 36 | B44: Pramila Devi | C44: 7870392175 | D44: Switch off | F44: Not Incoming | G44: Switch off | I44: Not Incoming
A45: 37 | B45: Ram Charan Paswan | C45: 7563054235 | D45: Connected | E45: CONFIRMED | G45: Connected | H45: CONFIRMED
A46: 38 | B46: Nitish Kumar | C46: 7004656149 | D46: Connected | E46: CONFIRMED | G46: Connected | H46: CONFIRMED
...

Sheet SLP Calling Update
A1: Serial No | B1: AC | C1: Name of Coordinator | D1: Total Data | E1: Call Connected | F1: Verified | G1: Not verified | H1: Not Received | I1: Busy | J1: Switch Off | K1: Wrong | L1: Call Back Later | M1: Remarks | N1: Meeting Date | O1: Remark For Training And Final Sheet
A2: 1 | B2: ROSERA | C2: Chandan Kumar | D2: =COUNTIFS('SLP Field Data'!K:K,B2,'SLP Field Data'!K:K,"<>") -> 48 | E2: =COUNTIFS('SLP Field Data'!K:K,B2,'SLP Field Data'!N:N,"Connected") -> 19 | F2: =COUNTIFS('SLP Field Data'!K:K,B2,'SLP Field Data'!AA:AA,"Verified") -> 9 | G2: =COUNTIFS('SLP Field Data'!K:K,B2,'SLP Field Data'!AA:AA,"Not Verified") -> 6 | H2: =COUNTIFS('SLP Field Data'!K:K,B2,'SLP Field Data'!N:N,"Not Received") -> 4 | I2: =COUNTIFS('SLP Field Data'!K:K,B2,'SLP Field Data'!N:N,"Busy") -> 0 | J2: =COUNTIFS('SLP Field Data'!K:K,B2,'SLP Field Data'!N:N,"Switch off") -> 6 | K2: =COUNTIFS('SLP Field Data'!K:K,B2,'SLP Field Data'!N:N,"Wrong No.") -> 16 | L2: =COUNTIFS('SLP Field Data'!K:K,B2,'SLP Field Data'!N:N,"Call Back Later") -> 3 | N2: 45854 | O2: Meeting done
A3: 2 | B3: GOPALGANJ | C3: Ajay Kumar Yadav | D3: =COUNTIFS('SLP Field Data'!K:K,B3,'SLP Field Data'!K:K,"<>") -> 38 | E3: =COUNTIFS('SLP Field Data'!K:K,B3,'SLP Field Data'!N:N,"Connected") -> 24 | F3: =COUNTIFS('SLP Field Data'!K:K,B3,'SLP Field Data'!AA:AA,"Verified") -> 21 | G3: =COUNTIFS('SLP Field Data'!K:K,B3,'SLP Field Data'!AA:AA,"Not Verified") -> 0 | H3: =COUNTIFS('SLP Field Data'!K:K,B3,'SLP Field Data'!N:N,"Not Received") -> 5 | I3: =COUNTIFS('SLP Field Data'!K:K,B3,'SLP Field Data'!N:N,"Busy") -> 0 | J3: =COUNTIFS('SLP Field Data'!K:K,B3,'SLP Field Data'!N:N,"Switch off") -> 4 | K3: =COUNTIFS('SLP Field Data'!K:K,B3,'SLP Field Data'!N:N,"Wrong No.") -> 2 | L3: =COUNTIFS('SLP Field Data'!K:K,B3,'SLP Field Data'!N:N,"Call Back Later") -> 2 | N3: 45860 | O3: Meeting done
A4: 3 | B4: ARWAL | C4: Captain Deepu | D4: =COUNTIFS('SLP Field Data'!K:K,B4,'SLP Field Data'!K:K,"<>") -> 41 | E4: =COUNTIFS('SLP Field Data'!K:K,B4,'SLP Field Data'!N:N,"Connected") -> 25 | F4: =COUNTIFS('SLP Field Data'!K:K,B4,'SLP Field Data'!AA:AA,"Verified") -> 25 | G4: =COUNTIFS('SLP Field Data'!K:K,B4,'SLP Field Data'!AA:AA,"Not Verified") -> 0 | H4: =COUNTIFS('SLP Field Data'!K:K,B4,'SLP Field Data'!N:N,"Not Received") -> 1 | I4: =COUNTIFS('SLP Field Data'!K:K,B4,'SLP Field Data'!N:N,"Busy") -> 7 | J4: =COUNTIFS('SLP Field Data'!K:K,B4,'SLP Field Data'!N:N,"Switch off") -> 5 | K4: =COUNTIFS('SLP Field Data'!K:K,B4,'SLP Field Data'!N:N,"Wrong No.") -> 2 | L4: =COUNTIFS('SLP Field Data'!K:K,B4,'SLP Field Data'!N:N,"Call Back Later") -> 1 | N4: 45865
A5: 4 | B5: CHIRAYA | C5: Tribhuvan Kumar | D5: =COUNTIFS('SLP Field Data'!K:K,B5,'SLP Field Data'!K:K,"<>") -> 27 | E5: =COUNTIFS('SLP Field Data'!K:K,B5,'SLP Field Data'!N:N,"Connected") -> 21 | F5: =COUNTIFS('SLP Field Data'!K:K,B5,'SLP Field Data'!AA:AA,"Verified") -> 20 | G5: =COUNTIFS('SLP Field Data'!K:K,B5,'SLP Field Data'!AA:AA,"Not Verified") -> 1 | H5: =COUNTIFS('SLP Field Data'!K:K,B5,'SLP Field Data'!N:N,"Not Received") -> 3 | I5: =COUNTIFS('SLP Field Data'!K:K,B5,'SLP Field Data'!N:N,"Busy") -> 1 | J5: =COUNTIFS('SLP Field Data'!K:K,B5,'SLP Field Data'!N:N,"Switch off") -> 2 | K5: =COUNTIFS('SLP Field Data'!K:K,B5,'SLP Field Data'!N:N,"Wrong No.") -> 0 | L5: =COUNTIFS('SLP Field Data'!K:K,B5,'SLP Field Data'!N:N,"Call Back Later") -> 0
A6: 5 | B6: JALE | C6: Ejaj ahmad | D6: =COUNTIFS('SLP Field Data'!K:K,B6,'SLP Field Data'!K:K,"<>") -> 44 | E6: =COUNTIFS('SLP Field Data'!K:K,B6,'SLP Field Data'!N:N,"Connected") -> 35 | F6: =COUNTIFS('SLP Field Data'!K:K,B6,'SLP Field Data'!AA:AA,"Verified") -> 35 | G6: =COUNTIFS('SLP Field Data'!K:K,B6,'SLP Field Data'!AA:AA,"Not Verified") -> 0 | H6: =COUNTIFS('SLP Field Data'!K:K,B6,'SLP Field Data'!N:N,"Not Received") -> 3 | I6: =COUNTIFS('SLP Field Data'!K:K,B6,'SLP Field Data'!N:N,"Busy") -> 0 | J6: =COUNTIFS('SLP Field Data'!K:K,B6,'SLP Field Data'!N:N,"Switch off") -> 3 | K6: =COUNTIFS('SLP Field Data'!K:K,B6,'SLP Field Data'!N:N,"Wrong No.") -> 0 | L6: =COUNTIFS('SLP Field Data'!K:K,B6,'SLP Field Data'!N:N,"Call Back Later") -> 3 | N6: 45860 | O6: Meeting done
A7: 6 | B7: PRANPUR | C7: Imbesat Ahmad | D7: =COUNTIFS('SLP Field Data'!K:K,B7,'SLP Field Data'!K:K,"<>") -> 47 | E7: =COUNTIFS('SLP Field Data'!K:K,B7,'SLP Field Data'!N:N,"Connected") -> 29 | F7: =COUNTIFS('SLP Field Data'!K:K,B7,'SLP Field Data'!AA:AA,"Verified") -> 29 | G7: =COUNTIFS('SLP Field Data'!K:K,B7,'SLP Field Data'!AA:AA,"Not Verified") -> 0 | H7: =COUNTIFS('SLP Field Data'!K:K,B7,'SLP Field Data'!N:N,"Not Received") -> 7 | I7: =COUNTIFS('SLP Field Data'!K:K,B7,'SLP Field Data'!N:N,"Busy") -> 9 | J7: =COUNTIFS('SLP Field Data'!K:K,B7,'SLP Field Data'!N:N,"Switch off") -> 2 | K7: =COUNTIFS('SLP Field Data'!K:K,B7,'SLP Field Data'!N:N,"Wrong No.") -> 0 | L7: =COUNTIFS('SLP Field Data'!K:K,B7,'SLP Field Data'!N:N,"Call Back Later") -> 0 | N7: 45866
A8: 7 | B8: PARO | C8: Md Sarfaraz | D8: =COUNTIFS('SLP Field Data'!K:K,B8,'SLP Field Data'!K:K,"<>") -> 22 | E8: =COUNTIFS('SLP Field Data'!K:K,B8,'SLP Field Data'!N:N,"Connected") -> 21 | F8: =COUNTIFS('SLP Field Data'!K:K,B8,'SLP Field Data'!AA:AA,"Verified") -> 21 | G8: =COUNTIFS('SLP Field Data'!K:K,B8,'SLP Field Data'!AA:AA,"Not Verified") -> 0 | H8: =COUNTIFS('SLP Field Data'!K:K,B8,'SLP Field Data'!N:N,"Not Received") -> 0 | I8: =COUNTIFS('SLP Field Data'!K:K,B8,'SLP Field Data'!N:N,"Busy") -> 0 | J8: =COUNTIFS('SLP Field Data'!K:K,B8,'SLP Field Data'!N:N,"Switch off") -> 1 | K8: =COUNTIFS('SLP Field Data'!K:K,B8,'SLP Field Data'!N:N,"Wrong No.") -> 0 | L8: =COUNTIFS('SLP Field Data'!K:K,B8,'SLP Field Data'!N:N,"Call Back Later") -> 0 | N8: 45862 | O8: Meeting done
A9: 8 | B9: KAHALGAON | C9: Pranav | D9: =COUNTIFS('SLP Field Data'!K:K,B9,'SLP Field Data'!K:K,"<>") -> 58 | E9: =COUNTIFS('SLP Field Data'!K:K,B9,'SLP Field Data'!N:N,"Connected") -> 39 | F9: =COUNTIFS('SLP Field Data'!K:K,B9,'SLP Field Data'!AA:AA,"Verified") -> 37 | G9: =COUNTIFS('SLP Field Data'!K:K,B9,'SLP Field Data'!AA:AA,"Not Verified") -> 0 | H9: =COUNTIFS('SLP Field Data'!K:K,B9,'SLP Field Data'!N:N,"Not Received") -> 4 | I9: =COUNTIFS('SLP Field Data'!K:K,B9,'SLP Field Data'!N:N,"Busy") -> 7 | J9: =COUNTIFS('SLP Field Data'!K:K,B9,'SLP Field Data'!N:N,"Switch off") -> 6 | K9: =COUNTIFS('SLP Field Data'!K:K,B9,'SLP Field Data'!N:N,"Wrong No.") -> 1 | L9: =COUNTIFS('SLP Field Data'!K:K,B9,'SLP Field Data'!N:N,"Call Back Later") -> 1 | N9: 45862 | O9: meeting done
A10: 9 | B10: AURANGABAD | C10: Abdullah Amin | D10: =COUNTIFS('SLP Field Data'!K:K,B10,'SLP Field Data'!K:K,"<>") -> 43 | E10: =COUNTIFS('SLP Field Data'!K:K,B10,'SLP Field Data'!N:N,"Connected") -> 24 | F10: =COUNTIFS('SLP Field Data'!K:K,B10,'SLP Field Data'!AA:AA,"Verified") -> 22 | G10: =COUNTIFS('SLP Field Data'!K:K,B10,'SLP Field Data'!AA:AA,"Not Verified") -> 3 | H10: =COUNTIFS('SLP Field Data'!K:K,B10,'SLP Field Data'!N:N,"Not Received") -> 7 | I10: =COUNTIFS('SLP Field Data'!K:K,B10,'SLP Field Data'!N:N,"Busy") -> 2 | J10: =COUNTIFS('SLP Field Data'!K:K,B10,'SLP Field Data'!N:N,"Switch off") -> 5 | K10: =COUNTIFS('SLP Field Data'!K:K,B10,'SLP Field Data'!N:N,"Wrong No.") -> 3 | L10: =COUNTIFS('SLP Field Data'!K:K,B10,'SLP Field Data'!N:N,"Call Back Later") -> 2
A11: 10 | B11: RAJGIR | C11: Raman | D11: =COUNTIFS('SLP Field Data'!K:K,B11,'SLP Field Data'!K:K,"<>") -> 42 | E11: =COUNTIFS('SLP Field Data'!K:K,B11,'SLP Field Data'!N:N,"Connected") -> 35 | F11: =COUNTIFS('SLP Field Data'!K:K,B11,'SLP Field Data'!AA:AA,"Verified") -> 32 | G11: =COUNTIFS('SLP Field Data'!K:K,B11,'SLP Field Data'!AA:AA,"Not Verified") -> 3 | H11: =COUNTIFS('SLP Field Data'!K:K,B11,'SLP Field Data'!N:N,"Not Received") -> 3 | I11: =COUNTIFS('SLP Field Data'!K:K,B11,'SLP Field Data'!N:N,"Busy") -> 0 | J11: =COUNTIFS('SLP Field Data'!K:K,B11,'SLP Field Data'!N:N,"Switch off") -> 2 | K11: =COUNTIFS('SLP Field Data'!K:K,B11,'SLP Field Data'!N:N,"Wrong No.") -> 2 | L11: =COUNTIFS('SLP Field Data'!K:K,B11,'SLP Field Data'!N:N,"Call Back Later") -> 0 | N11: 45864 | O11: meeting call done
A12: 11 | B12: KISHANGANJ | C12: Shums Uddin Ansari | D12: =COUNTIFS('SLP Field Data'!K:K,B12,'SLP Field Data'!K:K,"<>") -> 28 | E12: =COUNTIFS('SLP Field Data'!K:K,B12,'SLP Field Data'!N:N,"Connected") -> 25 | F12: =COUNTIFS('SLP Field Data'!K:K,B12,'SLP Field Data'!AA:AA,"Verified") -> 25 | G12: =COUNTIFS('SLP Field Data'!K:K,B12,'SLP Field Data'!AA:AA,"Not Verified") -> 0 | H12: =COUNTIFS('SLP Field Data'!K:K,B12,'SLP Field Data'!N:N,"Not Received") -> 1 | I12: =COUNTIFS('SLP Field Data'!K:K,B12,'SLP Field Data'!N:N,"Busy") -> 0 | J12: =COUNTIFS('SLP Field Data'!K:K,B12,'SLP Field Data'!N:N,"Switch off") -> 0 | K12: =COUNTIFS('SLP Field Data'!K:K,B12,'SLP Field Data'!N:N,"Wrong No.") -> 0 | L12: =COUNTIFS('SLP Field Data'!K:K,B12,'SLP Field Data'!N:N,"Call Back Later") -> 2 | N12: 45865
A13: 12 | B13: TIKARI | C13: Ashish Kumar | D13: =COUNTIFS('SLP Field Data'!K:K,B13,'SLP Field Data'!K:K,"<>") -> 30 | E13: =COUNTIFS('SLP Field Data'!K:K,B13,'SLP Field Data'!N:N,"Connected") -> 13 | F13: =COUNTIFS('SLP Field Data'!K:K,B13,'SLP Field Data'!AA:AA,"Verified") -> 13 | G13: =COUNTIFS('SLP Field Data'!K:K,B13,'SLP Field Data'!AA:AA,"Not Verified") -> 0 | H13: =COUNTIFS('SLP Field Data'!K:K,B13,'SLP Field Data'!N:N,"Not Received") -> 4 | I13: =COUNTIFS('SLP Field Data'!K:K,B13,'SLP Field Data'!N:N,"Busy") -> 3 | J13: =COUNTIFS('SLP Field Data'!K:K,B13,'SLP Field Data'!N:N,"Switch off") -> 6 | K13: =COUNTIFS('SLP Field Data'!K:K,B13,'SLP Field Data'!N:N,"Wrong No.") -> 2 | L13: =COUNTIFS('SLP Field Data'!K:K,B13,'SLP Field Data'!N:N,"Call Back Later") -> 0 | N13: 38560

Sheet ARWAL AC
A1: SLP List Assembly: ARWAL Training Date & Time: 27/07/25 Location: आंध्रचक, हाइ स्कूल ( रविदाश भगवान ) के पास main रोड पर, नियर शहर तेलपा Field Coordinator: CAPTAIN DEEPU
A6: Sr. No. | B6: Name | C6: Mobile Number | D6: Calling Status 26th July | E6: Confirmation Status | F6: Remarks
A7: 1 | B7: Subodh Kumar | C7: 7091332065 | D7: Connected | E7: CONFIRMED
A8: 2 | B8: Rajkumar | C8: 7488751378 | D8: Connected | E8: CONFIRMED
A9: 3 | B9: Ujjwal Kumar | C9: 8873613785 | D9: Connected | E9: CONFIRMED
A10: 4 | B10: Arjun Singh | C10: 9631229048 | D10: Switch off
A11: 5 | B11: Sikandar Kumar | C11: 7033959812 | D11: Connected | E11: CONFIRMED
A12: 6 | B12: Pappu Kumar | C12: 8757752901 | D12: Connected | E12: CONFIRMED
A13: 7 | B13: Sanjay Kumar | C13: 7484042954 | D13: Connected | E13: CONFIRMED
A14: 8 | B14: Pramila Kumari | C14: 9835600213 | D14: Connected | E14: CONFIRMED
A15: 9 | B15: Indu Kumari | C15: 9504143372 | D15: Connected | E15: CONFIRMED
A16: 10 | B16: Akshay Kumar | C16: 6206365883 | D16: Switch off
A17: 11 | B17: Vikas Kumar | C17: 9508083254 | D17: Connected | E17: CONFIRMED
A18: 12 | B18: Abhimanyu Kumar (Dr) | C18: 8002066561 | D18: Connected | E18: CONFIRMED
A19: 13 | B19: Amarendra Kumar | C19: 6204318716 | D19: Connected | E19: CONFIRMED
A20: 14 | B20: Satyendra Bind | C20: 8294945134 | D20: Connected | E20: CONFIRMED
A21: 15 | B21: Surendra Yadav | C21: 9771000297 | D21: Connected | E21: CONFIRMED
A22: 16 | B22: Ajay Yadav | C22: 8294946091 | D22: Connected | E22: CONFIRMED
A23: 17 | B23: Ramesh Kumar | C23: 9534652604 | D23: Connected | E23: CONFIRMED
A24: 18 | B24: Ranjit Kumar | C24: 9102776486 | D24: Connected | E24: CONFIRMED
A25: 19 | B25: Sunil Ram | C25: 7061992430 | D25: Connected | E25: CONFIRMED
A26: 20 | B26: Pintu Kumar | C26: 8310324048 | D26: Connected | E26: CONFIRMED
A27: 21 | B27: Ram Bihari Yadav | C27: 7257812106 | D27: Connected | E27: CONFIRMED
A28: 22 | B28: Manoj Kumar | C28: 7762887398 | D28: Not Received
A29: 23 | B29: Bachchan Rajvanshi | C29: 8298775638 | D29: Not Received
A30: 24 | B30: Sanjeet Kumar (Chainpur) | C30: 6203893706 | D30: Connected | E30: CONFIRMED
A31: 25 | B31: Nitish Kumar | C31: 9065585658 | D31: Connected | E31: CONFIRMED
B34: Vikas Kumar | C34: 7543966608
B35: Arvind Kumar | C35: 8340511206
B36: Pintu Kumar | C36: 8797564240
B37: Ajit Kumar | C37: 8804190210
B38: Ramashankar Kumar | C38: 9199540939
B39: Ravi Shankar Kumar | C39: 6207930631
B40: Pappu Kumar | C40: 6207930631
B41: VOLUNTEER
B43: Anil Kumar | C43: 7654158771
B44: Gautam Kumar | C44: 9065589656
B45: Arvind Kumari (Shri Ram Bigha) | C45: 8905077729
B46: Manoj Kumar | C46: 9525781036
B47: Anil Kumar | C47: 8873195113
...

Sheet TIKARI AC
A1: SLP List Assembly: TIKARI Training Date & Time: 27th JULY 9:00AM Location: Chhaavanee Mohalla, Infront of Masjid, Near Budhwa Mahade Asthan Hospital Road. Field Coordinator: Ashish Kumar
A8: Sr. No. | B8: Name | C8: Mobile Number | D8: 26th July Calling Status | E8: Confirmation Status | F8: Remarks
A9: 1 | B9: Prince Kumar | C9: 7319960500 | D9: Busy
A10: 2 | B10: Ritish Kumar | C10: 9798263918 | D10: Switch off
A11: 3 | B11: Pritam Kumar | C11: 9097937103 | D11: Connected | E11: CONFIRMED
A12: 4 | B12: Barjesh Kumar | C12: 9060365941 | D12: Connected | E12: CONFIRMED
A13: 5 | B13: Jitendra Kumar | C13: 6203490074 | D13: Connected | E13: CONFIRMED
A14: 6 | B14: Omprey Yadav | C14: 9631649075 | D14: Connected | E14: CONFIRMED
A15: 7 | B15: Rubi Devi | C15: 9608783425 | D15: Not Received
A16: 8 | B16: Shudesh Kumar | C16: 878996473 | D16: Switch off
A17: 9 | B17: Md. Tahuid | C17: 9431292623 | D17: Not Received
A18: 10 | B18: Ranjan Yadav | C18: 9006491194 | D18: Not Received
A19: 11 | B19: Dablu Kumar | C19: 6204192749 | D19: Connected | E19: NOT CONFIRMED
A20: 12 | B20: Guddu Kumar | C20: 8709532549 | D20: Not Received
A21: 13 | B21: Aman Kumar | C21: 6203208472 | D21: Connected | E21: NOT CONFIRMED | F21: wrong profile
A22: 14 | B22: Aman Gupta | C22: 9279038472 | D22: Connected | E22: CONFIRMED
A23: 15 | B23: Aman Rathor | C23: 7667730455 | D23: Connected | E23: CONFIRMED
A24: 16 | B24: Rajnish Kumar | C24: 6203303043 | D24: Switch off
A25: 17 | B25: Chitranjan Kumar | C25: 6200141584 | D25: Not Received
A26: 18 | B26: Sourav Kumar | C26: 9241697868 | D26: Busy
A27: 19 | B27: Randhir Kumar | C27: 7480929489 | D27: Connected | E27: CONFIRMED
A28: 20 | B28: Kush Ranjan | C28: 8797639217 | D28: Not Received
A29: 21 | B29: Gunjan Kumar | C29: 6205340964 | D29: Not Received
A30: 22 | B30: Ranjan Kumar | C30: 8791639217 | D30: Switch off
A31: 23 | B31: Ayush Kumar | C31: 9122244868 | D31: Connected | E31: CONFIRMED
A32: 24 | B32: Sonu Kumar | C32: 9693404461 | D32: Connected | E32: CONFIRMED
A33: 25 | B33: Rajveer Singh | C33: 6204731272 | D33: Connected | E33: CONFIRMED
A34: 26 | B34: Md. Abdul Hamir | C34: 7541031168 | D34: Call Back Later
A35: 27 | B35: Robin Sharma | C35: 980188133 | D35: Switch off
A36: 28 | B36: Upendra Kumar | C36: 9771297370 | D36: Connected | E36: CONFIRMED
A37: 29 | B37: Gunjan Devi | C37: 7766875105 | D37: Connected | E37: CONFIRMED
A38: 30 | B38: Akshay Choudhary | C38: 7488308839 | D38: Connected | E38: NOT CONFIRMED
A43: ASSEMBLY COORDINATOR (LEADER NAME) | B43: NAME | C43: NUMBER | D43: AGE | E43: GENDER | F43: PROFESSION | G43: RELIGION | H43: CATEGORY | I43: CASTE | J43: DISTRICT | K43: ASSEMBLY | L43: BLOCK | M43: PANCHAYAT | N43: Calling Status | O43: 1. क्या आप राजनीतिक या सामाजिक कार्य में रूचि रखते हैं? (हां/नहीं) | P43: 2. क्या आप वर्तमान में किसी सामाजिक या राजनैतिक संगठन से जुड़े हैं? (हाँ / नहीं) | Q43: संगठन का नाम (यदि हाँ): | R43: भूमिका (1-2 शब्द): | S43: 3. आपने अब तक अपने क्षेत्र में कोई सामाजिक या जन सरोकार का कार्य किया है? (हाँ / नहीं) | T43: यदि हाँ, तो एक उदाहरण दें: | U43: 4. क्या आपने कभी किसी जनप्रतिनिधि से जनता के मुद्दों को लेकर बात की है? (हाँ / नहीं) | V43: यदि हाँ, तो मुद्दा: | W43: 5. सामाजिक न्याय और समानता आपके लिए कितनी महत्वपूर्ण है? (बहुत / कुछ हद तक / नहीं) | X43: 6. क्या आप मानते हैं कि भारतीय संविधान की बातें – न्याय, स्वतंत्रता, समानता, बंधुत्व – ज़मीनी स्तर तक पहुंचें? (हाँ / नहीं) | Y43: 7. क्या आप कांग्रेस पार्टी द्वारा चलाए जा रहे संविधान लीडरशिप प्रोग्राम के बारे में जानते हैं? (हां/नहीं) (यदि नहीं तो संविधान लीडरशिप प्रोग्राम के बारे में जानकारी- ) | Z43: 8. क्या आप इस प्रोग्राम में नेतृत्व की भूमिका निभाने को तैयार हैं? (हाँ / नहीं / विचार कर रहा/रही हूं) | AA43: Verification Status | AB43: Remarks
A44: ASHISH KUMAR (TIKARI) | B44: Prince Kumar | C44: 7319960500 | D44: 35 | E44: Male | F44: socal worker | G44: muslim | H44: General | I44: shekh | J44: Gaya | K44: TIKARI | L44: kishanganj | M44: kishanganj | N44: Connected | O44: Yes | P44: Yes | Q44: congress | R44: town President | S44: Yes | T44: Road light | U44: Yes | V44: ramjan river | W44: Bahut | X44: Yes | Y44: Yes | Z44: Yes | AA44: Verified
B45: Ritish Kumar | C45: 9798263918 | J45: Gaya | K45: TIKARI | N45: Switch off
B46: Pritam Kumar | C46: 9097937103 | J46: Gaya | K46: TIKARI | N46: Not Received
B47: Barjesh Kumar | C47: 9060365941 | D47: 40 | E47: Male | F47: company | G47: Hindu | H47: OBC | I47: chandrawansi | J47: Gaya | K47: TIKARI | L47: Tikari | M47: mussi | N47: Connected | O47: Yes | P47: NO | S47: Yes | T47: unemployment | U47: Yes | V47: Development | W47: Bahut | X47: Yes | Y47: NO | Z47: Yes | AA47: Verified
B48: Jitendra Kumar | C48: 6203490074 | D48: 25 | E48: Male | F48: Student | G48: Hindu | H48: OBC | I48: Yadav | J48: Gaya | K48: TIKARI | L48: Tikari | M48: Palwar | N48: Connected | O48: Yes | P48: Yes | Q48: Congress | S48: NO | U48: NO | W48: Bahut | X48: Yes | Y48: Yes | Z48: Yes | AA48: Verified
B49: Omprey Yadav | C49: 9631649075 | J49: Gaya | K49: TIKARI | N49: Switch off
B50: Rubi Devi | C50: 9608783425 | J50: Gaya | K50: TIKARI | N50: Not Received
...

Sheet PRANPUR AC
A1: SLP List Assembly: PRANPUR Training Date & Time: 28/07/25 11:00am Location: Daroga bagicha aazam nagar Field Coordinator: MD IMBESAT AHMAD
A6: Sr. No. | B6: Name | C6: Mobile Number | D6: Calling Status 26th July | E6: Confirmation Status | F6: Remarks
A7: 1 | B7: Md Haseeb | C7: 7520145681 | D7: Connected | E7: CONFIRMED
A8: 2 | B8: Md Sami Akhtar | C8: 9939489345 | D8: Connected | E8: CONFIRMED
A9: 3 | B9: Md Jahangir Alam | C9: 9006727605, 6206600906 | D9: Connected | E9: CONFIRMED
A10: 4 | B10: Md Firoj | C10: 7260979038, 7633900190 | D10: Connected | E10: CONFIRMED
A11: 5 | B11: Md Sajid Ali | C11: 7903381812 | D11: Connected | E11: CONFIRMED
A12: 6 | B12: Md Tanveer Shah | C12: 9264167757 | D12: Connected | E12: CONFIRMED
A13: 7 | B13: Md Hashim | C13: 9798147335 | D13: Connected | E13: CONFIRMED
A14: 8 | B14: Firoz Alam | C14: 8873758984 | D14: Connected | E14: CONFIRMED
A15: 9 | B15: Md Firoz Alam | C15: 9661518971 | D15: Connected | E15: CONFIRMED
A16: 10 | B16: Md Anwar Alam | C16: 8210787306 | D16: Connected | E16: CONFIRMED
A17: 11 | B17: Md Shabbir | C17: 7903915451 | D17: Connected | E17: CONFIRMED
A18: 12 | B18: Sukhdev Rai | C18: 9939026809 | D18: Connected | E18: CONFIRMED
A19: 13 | B19: Md Mamnoon Akhtar | C19: 7631212149 | D19: Connected | E19: CONFIRMED
A20: 14 | B20: Mir Sultan Ahmad | C20: 7367838076 | D20: Connected | E20: CONFIRMED
A21: 15 | B21: Md Mushfique Alam | C21: 9508652602 | D21: Connected | E21: CONFIRMED
A22: 16 | B22: Md Shah Jahan | C22: 9113325794 | D22: Connected | E22: CONFIRMED
... A35: 29 | B35: MD Sajid Alam | C35: 9931730841 | D35: Connected | E35: CONFIRMED
B36: Ranjeet Ravi Das | C36: 7643067272
B37: Govind Rai | C37: 8252412964
B38: Zulfiqar Ansari | C38: 7739916619
B39: Dharmanand Mistry | C39: 9661817387, 8084037146
B40: Raushan Jamil | C40: 7320883378
B41: Md Nezamuddin | C41: 7033056676
B42: Pawan Kumar Poddar | C42: 9996405211
B43: Akhtar | C43: 7033013470
B44: Md Sarfaraz | C44: 7543848949
B45: Sanjay Rai | C45: 8092728916
B46: Md Naushad Alam | C46: 9955445933
B47: Guddu | C47: 7091361785
B48: Pradip Kumar Rai | C48: 8084852393
B49: Md Shadab Karim | C49: 7488257331
B50: Md Akhtar | C50: 9304212043
B51: Pappu Singh | C51: 6299737282
... B53: Md Sanaullah | C53: 7739969599
A56: ASSEMBLY COORDINATOR (LEADER NAME) | B56: NAME | C56: NUMBER | D56: AGE | E56: GENDER | F56: PROFESSION | G56: RELIGION | H56: CATEGORY | I56: CASTE | J56: DISTRICT | K56: ASSEMBLY | L56: BLOCK | M56: PANCHAYAT | N56: Calling Status | O56: 1. क्या आप राजनीतिक या सामाजिक कार्य में रूचि रखते हैं? (हां/नहीं) | P56: 2. क्या आप वर्तमान में किसी सामाजिक या राजनैतिक संगठन से जुड़े हैं? (हाँ / नहीं) | Q56: संगठन का नाम (यदि हाँ): | R56: भूमिका (1-2 शब्द): | S56: 3. आपने अब तक अपने क्षेत्र में कोई सामाजिक या जन सरोकार का कार्य किया है? (हाँ / नहीं) | T56: यदि हाँ, तो एक उदाहरण दें: | U56: 4. क्या आपने कभी किसी जनप्रतिनिधि से जनता के मुद्दों को लेकर बात की है? (हाँ / नहीं) | V56: यदि हाँ, तो मुद्दा: | W56: 5. सामाजिक न्याय और समानता आपके लिए कितनी महत्वपूर्ण है? (बहुत / कुछ हद तक / नहीं) | X56: 6. क्या आप मानते हैं कि भारतीय संविधान की बातें – न्याय, स्वतंत्रता, समानता, बंधुत्व – ज़मीनी स्तर तक पहुंचें? (हाँ / नहीं) | Y56: 7. क्या आप कांग्रेस पार्टी द्वारा चलाए जा रहे संविधान लीडरशिप प्रोग्राम के बारे में जानते हैं? (हां/नहीं) (यदि नहीं तो संविधान लीडरशिप प्रोग्राम के बारे में जानकारी- ) | Z56: 8. क्या आप इस प्रोग्राम में नेतृत्व की भूमिका निभाने को तैयार हैं? (हाँ / नहीं / विचार कर रहा/रही हूं) | AA56: Verification Status | AB56: Remarks
A57: MD IMBESAT AHMAD (7838622990) | B57: Md Haseeb | C57: 7520145681 | D57: 54 | E57: Male | F57: farmer | G57: muslim | H57: general | I57: muslim | J57: Katihar | K57: PRANPUR | L57: Aajamnagar | M57: salmari | N57: Connected | O57: Yes | P57: Yes | Q57: congress | R57: vidhan sabha mahasachiv | S57: Yes | T57: white tshirt ke bare me btana or mai behan maan yojna ki jankari dena | U57: Yes | V57: bjp gov ka ghotala ke bare me btana ye sb ke mudhe pr baat kiye hai | W57: bhut | X57: Yes | Y57: Yes | Z57: Yes | AA57: Verified
B58: Md Sami Akhtar | C58: 9939489345 | D58: 45 | E58: Male | F58: tax sachiv hai | G58: muslim | H58: general | I58: muslim | J58: Katihar | K58: PRANPUR | L58: Aajamnagar | M58: salmari | N58: Connected | O58: Yes | P58: NO | S58: Yes | T58: mukhiya ke election me bhagidari hote h | U58: Yes | V58: samaj ke vyasthao | W58: bhut | X58: Yes | Y58: Yes | Z58: Yes | AA58: Verified
B59: Md Jahangir Alam | C59: 9006727605, 6206600906 | E59: Male | F59: teacher hai | G59: muslim | H59: sc | I59: muslim | J59: Katihar | K59: PRANPUR | L59: Aajamnagar | M59: salmari | N59: Connected | O59: Yes | P59: Yes | Q59: congress | R59: panchayat sarpanch hai | S59: NO | U59: NO | W59: kuch had tak | X59: Yes | Y59: Yes | Z59: Yes | AA59: Verified
...

Sheet KISHANGANJ AC
A1: SLP List Assembly: KISHANGANJ Training Date & Time: 27 July 2025, 10:00 AM Location: Rehmat Nagar Karbala Kishanganj Field Coordinator: SHUMS UDDIN ANSARI
A6: Sr. No. | B6: Name | C6: Mobile Number | D6: 26th July Calling Status | E6: Confirmation Status | F6: Remarks
A7: 1 | B7: Amjad Alam | C7: 9430081363 | D7: Connected | E7: CONFIRMED
A8: 2 | B8: Anchan Devi | C8: 9608007073 | D8: Connected | E8: CONFIRMED
A9: 3 | B9: Ashfaq Alam | C9: 7908608094 | D9: Connected | E9: CONFIRMED
A10: 4 | B10: Badrul Alam | C10: 9564198822 | D10: Busy
A11: 5 | B11: Budhan Singh | C11: 6206192169 | D11: Connected | E11: CONFIRMED
A12: 6 | B12: Farhat | C12: 6201816401 | D12: Not Received
A13: 7 | B13: Faryaz Alam | C13: 7667519336 | D13: Connected | E13: CONFIRMED
A14: 8 | B14: Gultaz | C14: 9241370743 | D14: Not Received
A15: 9 | B15: Jabbar | C15: 8521888445 | D15: Not Received
A16: 10 | B16: Jahangir Alam | C16: 9933904605 | D16: Connected | E16: CONFIRMED
A17: 11 | B17: Md Ahsan | C17: 9478685134 | D17: Not Received
A18: 12 | B18: Md Kabir | C18: 9113700252 | D18: Connected | E18: CONFIRMED
A19: 13 | B19: Md Rehan | C19: 7292830314 | D19: Connected | E19: CONFIRMED
A20: 14 | B20: Meraj Alam | C20: 6201981464 | D20: Connected | E20: CONFIRMED
A21: 15 | B21: Mohd Resu | C21: 7739320475 | D21: Connected | E21: CONFIRMED
A22: 16 | B22: Mohd Shadab | C22: 9234539898 | D22: Connected | E22: CONFIRMED
A23: 17 | B23: Muftadi | C23: 6299419122 | D23: Connected | E23: CONFIRMED
A24: 18 | B24: Radha Kumari | C24: 6202309302 | D24: Connected | E24: CONFIRMED
A25: 19 | B25: Rakesh Das | C25: 6201383079 | D25: Connected | E25: CONFIRMED
A26: 20 | B26: Sanjay | C26: 9631247871 | D26: Connected | E26: CONFIRMED
A27: 21 | B27: Sanjay Saini | C27: 8002783520 | D27: Connected | E27: CONFIRMED
A28: 22 | B28: Thabasum | C28: 9835962089 | D28: Connected | E28: CONFIRMED
A29: 23 | B29: Amanullah | C29: 9693567984 | D29: Not Received
A30: 24 | B30: Shabir Alam | C30: 6201595936 | D30: Connected | E30: CONFIRMED
A31: 25 | B31: Nayeem Aktar | C31: 9955090896 | D31: Connected | E31: CONFIRMED
A32: 26 | B32: Kausher Alam | C32: 7992376020 | D32: Connected | E32: CONFIRMED
A33: 27 | B33: Kishor Kumar | C33: 9142165692 | D33: Connected | E33: CONFIRMED
A34: 28 | B34: Shadab Alam | C34: 6204005191 | D34: Connected | E34: CONFIRMED
A36: ASSEMBLY COORDINATOR (LEADER NAME) | B36: NAME | C36: NUMBER | D36: AGE | E36: GENDER | F36: PROFESSION | G36: RELIGION | H36: CATEGORY | I36: CASTE | J36: DISTRICT | K36: ASSEMBLY | L36: BLOCK | M36: PANCHAYAT | N36: Calling Status | O36: 1. क्या आप राजनीतिक या सामाजिक कार्य में रूचि रखते हैं? (हां/नहीं) | P36: 2. क्या आप वर्तमान में किसी सामाजिक या राजनैतिक संगठन से जुड़े हैं? (हाँ / नहीं) | Q36: संगठन का नाम (यदि हाँ): | R36: भूमिका (1-2 शब्द): | S36: 3. आपने अब तक अपने क्षेत्र में कोई सामाजिक या जन सरोकार का कार्य किया है? (हाँ / नहीं) | T36: यदि हाँ, तो एक उदाहरण दें: | U36: 4. क्या आपने कभी किसी जनप्रतिनिधि से जनता के मुद्दों को लेकर बात की है? (हाँ / नहीं) | V36: यदि हाँ, तो मुद्दा: | W36: 5. सामाजिक न्याय और समानता आपके लिए कितनी महत्वपूर्ण है? (बहुत / कुछ हद तक / नहीं) | X36: 6. क्या आप मानते हैं कि भारतीय संविधान की बातें – न्याय, स्वतंत्रता, समानता, बंधुत्व – ज़मीनी स्तर तक पहुंचें? (हाँ / नहीं) | Y36: 7. क्या आप कांग्रेस पार्टी द्वारा चलाए जा रहे संविधान लीडरशिप प्रोग्राम के बारे में जानते हैं? (हां/नहीं) (यदि नहीं तो संविधान लीडरशिप प्रोग्राम के बारे में जानकारी- ) | Z36: 8. क्या आप इस प्रोग्राम में नेतृत्व की भूमिका निभाने को तैयार हैं? (हाँ / नहीं / विचार कर रहा/रही हूं) | AA36: Verification Status | AB36: Remarks
A37: SHUMS UDDIN ANSARI | B37: Amjad Alam | C37: 9430081363 | D37: 35 | E37: Male | F37: private work | G37: muslim | H37: junral | I37: Sekh | J37: kishanganj | K37: KISHANGANJ | L37: kishanganj | M37: Municipal corporation | N37: Connected | O37: Yes | P37: Yes | Q37: congress | R37: nager yoba | S37: Yes | T37: social work | U37: Yes | V37: ramjan nadi | W37: Bahut | X37: Yes | Y37: Yes | Z37: Yes | AA37: Verified
B38: Anchan Devi | C38: 9608007073 | D38: 33 | E38: Female | F38: house wife | G38: Hindu | H38: OBC | I38: Mahto | J38: kishanganj | K38: KISHANGANJ | L38: kishanganj | M38: municipal corporation | N38: Connected | O38: Yes | P38: NO | S38: NO | U38: NO | W38: Kuch Had Tak | X38: Yes | Y38: NO | Z38: Yes | AA38: Verified
B39: Ashfaq Alam | C39: 7908608094 | D39: 33 | E39: Male | F39: business | G39: muslim | H39: EBC | J39: kishanganj | K39: KISHANGANJ | L39: pothia | M39: duban ucchi | N39: Connected | O39: Yes | P39: Yes | Q39: congress | S39: Yes | T39: helping people | U39: Yes | V39: devlopment | W39: Bahut | X39: Yes | Y39: Yes | Z39: Yes | AA39: Verified
B40: Badrul Alam | C40: 9564198822 | D40: 32 | E40: Male | F40: ward members | G40: muslim | H40: OBC | J40: kishanganj | K40: KISHANGANJ | L40: pothia | M40: gourukhal | N40: Connected | O40: Yes | P40: Yes | Q40: congress | S40: NO | U40: NO | W40: Bahut | X40: Yes | Y40: Yes | Z40: Yes | AA40: Verified
B41: Budhan Singh | C41: 6206192169 | D41: 36 | E41: Male | F41: NGO | G41: Hindu | H41: obc | I41: ranbabsi | J41: kishanganj | K41: KISHANGANJ | L41: pothia | M41: mirjapur | N41: Connected | O41: Yes | P41: Yes | Q41: kisan ykta | R41: a/c | S41: Yes | T41: helping people | U41: NO | W41: Bahut | X41: Yes | Y41: Yes | Z41: Yes | AA41: Verified
